<sdf version='1.8'>
  <model name='turtlebot3_burger'>
    <link name='base_footprint'>
      <inertial>
        <pose>-0.00429 0 0.030734 0 -0 0</pose>
        <mass>0.944735</mass>
        <inertia>
          <ixx>0.00717896</ixx>
          <ixy>-1.22941e-05</ixy>
          <ixz>0.00057674</ixz>
          <iyy>0.00721804</iyy>
          <iyz>-5.01209e-06</iyz>
          <izz>0.00413858</izz>
        </inertia>
      </inertial>
      <collision name='base_footprint_fixed_joint_lump__base_link_collision'>
        <pose>-0.032 0 0.08 0 -0 0</pose>
        <geometry>
          <box>
            <size>0.14 0.14 0.143</size>
          </box>
        </geometry>
      </collision>
      <collision name='base_footprint_fixed_joint_lump__caster_back_link_collision_1'>
        <pose>-0.081 1e-06 0.005 -1.57 0 0</pose>
        <geometry>
          <box>
            <size>0.03 0.009 0.02</size>
          </box>
        </geometry>
      </collision>
      <collision name='base_footprint_fixed_joint_lump__base_scan_collision_2'>
        <pose>-0.017 0 0.1755 0 -0 0</pose>
        <geometry>
          <cylinder>
            <length>0.0315</length>
            <radius>0.055</radius>
          </cylinder>
        </geometry>
        <surface>
          <contact>
            <ode/>
          </contact>
          <friction>
            <ode/>
          </friction>
        </surface>
      </collision>
      <visual name='base_footprint_fixed_joint_lump__base_link_visual'>
        <pose>-0.032 0 0.01 0 -0 0</pose>
        <geometry>
          <mesh>
            <scale>0.001 0.001 0.001</scale>
            <uri>file:///opt/ros/humble/share/turtlebot3_description/meshes/bases/burger_base.stl</uri>
          </mesh>
        </geometry>
      </visual>
      <visual name='base_footprint_fixed_joint_lump__base_scan_visual_1'>
        <pose>-0.032 0 0.182 0 -0 0</pose>
        <geometry>
          <mesh>
            <scale>0.001 0.001 0.001</scale>
            <uri>file:///opt/ros/humble/share/turtlebot3_description/meshes/sensors/lds.stl</uri>
          </mesh>
        </geometry>
      </visual>
    </link>
    <joint name='wheel_left_joint' type='revolute'>
      <pose relative_to='base_footprint'>0 0.08 0.033 -1.57 0 0</pose>
      <parent>base_footprint</parent>
      <child>wheel_left_link</child>
      <axis>
        <xyz>0 0 1</xyz>
        <limit>
          <lower>-1e+16</lower>
          <upper>1e+16</upper>
        </limit>
        <dynamics>
          <spring_reference>0</spring_reference>
          <spring_stiffness>0</spring_stiffness>
        </dynamics>
      </axis>
    </joint>
    <link name='wheel_left_link'>
      <pose relative_to='wheel_left_joint'>0 0 0 0 -0 0</pose>
      <inertial>
        <pose>0 0 0 0 -0 0</pose>
        <mass>0.0284989</mass>
        <inertia>
          <ixx>1.11756e-05</ixx>
          <ixy>-4.23698e-11</ixy>
          <ixz>-5.93817e-09</ixz>
          <iyy>1.11924e-05</iyy>
          <iyz>-1.44001e-11</iyz>
          <izz>2.07126e-05</izz>
        </inertia>
      </inertial>
      <collision name='wheel_left_link_collision'>
        <pose>0 0 0 0 -0 0</pose>
        <geometry>
          <cylinder>
            <length>0.018</length>
            <radius>0.033</radius>
          </cylinder>
        </geometry>
      </collision>
      <visual name='wheel_left_link_visual'>
        <pose>0 0 0 1.57 -0 0</pose>
        <geometry>
          <mesh>
            <scale>0.001 0.001 0.001</scale>
            <uri>file:///opt/ros/humble/share/turtlebot3_description/meshes/wheels/left_tire.stl</uri>
          </mesh>
        </geometry>
      </visual>
    </link>
    <joint name='wheel_right_joint' type='revolute'>
      <pose relative_to='base_footprint'>0 -0.08 0.033 -1.57 0 0</pose>
      <parent>base_footprint</parent>
      <child>wheel_right_link</child>
      <axis>
        <xyz>0 0 1</xyz>
        <limit>
          <lower>-1e+16</lower>
          <upper>1e+16</upper>
        </limit>
        <dynamics>
          <spring_reference>0</spring_reference>
          <spring_stiffness>0</spring_stiffness>
        </dynamics>
      </axis>
    </joint>
    <link name='wheel_right_link'>
      <pose relative_to='wheel_right_joint'>0 0 0 0 -0 0</pose>
      <inertial>
        <pose>0 0 0 0 -0 0</pose>
        <mass>0.0284989</mass>
        <inertia>
          <ixx>1.11756e-05</ixx>
          <ixy>-4.23698e-11</ixy>
          <ixz>-5.93817e-09</ixz>
          <iyy>1.11924e-05</iyy>
          <iyz>-1.44001e-11</iyz>
          <izz>2.07126e-05</izz>
        </inertia>
      </inertial>
      <collision name='wheel_right_link_collision'>
        <pose>0 0 0 0 -0 0</pose>
        <geometry>
          <cylinder>
            <length>0.018</length>
            <radius>0.033</radius>
          </cylinder>
        </geometry>
      </collision>
      <visual name='wheel_right_link_visual'>
        <pose>0 0 0 1.57 -0 0</pose>
        <geometry>
          <mesh>
            <scale>0.001 0.001 0.001</scale>
            <uri>file:///opt/ros/humble/share/turtlebot3_description/meshes/wheels/right_tire.stl</uri>
          </mesh>
        </geometry>
      </visual>
    </link>
    <!-- LIDAR külön linken, gamma mintára -->
    <link name="ouster_link">
      <pose>0 0 0.25 0 0 0</pose>
      <inertial>
        <mass>0.01</mass>
        <inertia>
          <ixx>1e-6</ixx>
          <iyy>1e-6</iyy>
          <izz>1e-6</izz>
          <ixy>0</ixy>
          <ixz>0</ixz>
          <iyz>0</iyz>
        </inertia>
      </inertial>
      <visual name="visual">
        <geometry>
          <box>
            <size>0.05 0.05 0.05</size>
          </box>
        </geometry>
      </visual>
      <sensor name="ouster" type="gpu_lidar">
        <topic>/model/turtlebot3/scan</topic>
        <frame>ouster_link</frame>
        <update_rate>10</update_rate>
        <ray>
          <scan>
            <horizontal>
              <samples>640</samples>
              <resolution>1</resolution>
              <min_angle>-3.14159</min_angle>
              <max_angle>3.14159</max_angle>
            </horizontal>
            <vertical>
              <samples>1</samples>
              <resolution>1</resolution>
              <min_angle>0</min_angle>
              <max_angle>0</max_angle>
            </vertical>
          </scan>
          <range>
            <min>0.08</min>
            <max>30.0</max>
            <resolution>0.01</resolution>
          </range>
        </ray>
        <alwaysOn>1</alwaysOn>
        <visualize>true</visualize>
      </sensor>
    </link>
    <joint name="ouster_fixed_joint" type="fixed">
      <parent>base_footprint</parent>
      <child>ouster_link</child>
    </joint>
    <static>0</static>
    <plugin name='ignition::gazebo::systems::DiffDrive' filename='libignition-gazebo-diff-drive-system.so'>
      <left_joint>wheel_left_joint</left_joint>
      <right_joint>wheel_right_joint</right_joint>
      <wheel_separation>0.16</wheel_separation>
      <wheel_radius>0.033</wheel_radius>
      <topic>/model/turtlebot3/cmd_vel</topic>
    </plugin>
  </model>
</sdf>
